WARNING 2018-08-24 17:11:15,717 base 152 Not Found: /verifications/imagecodes/bef9bdef-48f8-4a43-b55f-ed14f610f4ab/
WARNING 2018-08-24 17:11:15,721 basehttp 124 "GET /verifications/imagecodes/bef9bdef-48f8-4a43-b55f-ed14f610f4ab/ HTTP/1.1" 404 2113
INFO 2018-08-24 17:12:09,052 basehttp 124 "GET / HTTP/1.1" 200 1714
INFO 2018-08-24 17:12:14,108 basehttp 124 "GET /admin HTTP/1.1" 301 0
INFO 2018-08-24 17:12:14,186 basehttp 124 "GET /admin/ HTTP/1.1" 302 0
INFO 2018-08-24 17:12:14,348 basehttp 124 "GET /admin/login/?next=/admin/ HTTP/1.1" 200 1652
INFO 2018-08-24 17:12:14,391 basehttp 124 "GET /static/admin/css/base.css HTTP/1.1" 200 16066
INFO 2018-08-24 17:12:14,399 basehttp 124 "GET /static/admin/css/login.css HTTP/1.1" 200 1203
INFO 2018-08-24 17:12:14,500 basehttp 124 "GET /static/admin/css/fonts.css HTTP/1.1" 200 423
INFO 2018-08-24 17:12:14,586 basehttp 124 "GET /static/admin/fonts/Roboto-Regular-webfont.woff HTTP/1.1" 200 80304
INFO 2018-08-24 17:12:14,588 basehttp 124 "GET /static/admin/fonts/Roboto-Light-webfont.woff HTTP/1.1" 200 81348
ERROR 2018-09-04 22:32:19,627 exception 135 Internal Server Error: /users/usernames/xiaoming/count/
Traceback (most recent call last):
  File "/home/python/.virtualenvs/django_py3_1.11_02/lib/python3.5/site-packages/django/core/handlers/exception.py", line 41, in inner
    response = get_response(request)
  File "/home/python/.virtualenvs/django_py3_1.11_02/lib/python3.5/site-packages/django/core/handlers/base.py", line 187, in _get_response
    response = self.process_exception_by_middleware(e, request)
  File "/home/python/.virtualenvs/django_py3_1.11_02/lib/python3.5/site-packages/django/core/handlers/base.py", line 185, in _get_response
    response = wrapped_callback(request, *callback_args, **callback_kwargs)
  File "/home/python/.virtualenvs/django_py3_1.11_02/lib/python3.5/site-packages/django/views/decorators/csrf.py", line 58, in wrapped_view
    return view_func(*args, **kwargs)
  File "/home/python/.virtualenvs/django_py3_1.11_02/lib/python3.5/site-packages/django/views/generic/base.py", line 68, in view
    return self.dispatch(request, *args, **kwargs)
  File "/home/python/.virtualenvs/django_py3_1.11_02/lib/python3.5/site-packages/rest_framework/views.py", line 483, in dispatch
    response = self.handle_exception(exc)
  File "/home/python/.virtualenvs/django_py3_1.11_02/lib/python3.5/site-packages/rest_framework/views.py", line 443, in handle_exception
    self.raise_uncaught_exception(exc)
  File "/home/python/.virtualenvs/django_py3_1.11_02/lib/python3.5/site-packages/rest_framework/views.py", line 480, in dispatch
    response = handler(request, *args, **kwargs)
TypeError: get() got an unexpected keyword argument 'username'
ERROR 2018-09-04 22:32:19,753 basehttp 124 "GET /users/usernames/xiaoming/count/ HTTP/1.1" 500 18558
ERROR 2018-09-04 22:32:59,827 exception 135 Internal Server Error: /users/usernames/xiaoming/count/
Traceback (most recent call last):
  File "/home/python/.virtualenvs/django_py3_1.11_02/lib/python3.5/site-packages/django/core/handlers/exception.py", line 41, in inner
    response = get_response(request)
  File "/home/python/.virtualenvs/django_py3_1.11_02/lib/python3.5/site-packages/django/core/handlers/base.py", line 187, in _get_response
    response = self.process_exception_by_middleware(e, request)
  File "/home/python/.virtualenvs/django_py3_1.11_02/lib/python3.5/site-packages/django/core/handlers/base.py", line 185, in _get_response
    response = wrapped_callback(request, *callback_args, **callback_kwargs)
  File "/home/python/.virtualenvs/django_py3_1.11_02/lib/python3.5/site-packages/django/views/decorators/csrf.py", line 58, in wrapped_view
    return view_func(*args, **kwargs)
  File "/home/python/.virtualenvs/django_py3_1.11_02/lib/python3.5/site-packages/django/views/generic/base.py", line 68, in view
    return self.dispatch(request, *args, **kwargs)
  File "/home/python/.virtualenvs/django_py3_1.11_02/lib/python3.5/site-packages/rest_framework/views.py", line 483, in dispatch
    response = self.handle_exception(exc)
  File "/home/python/.virtualenvs/django_py3_1.11_02/lib/python3.5/site-packages/rest_framework/views.py", line 443, in handle_exception
    self.raise_uncaught_exception(exc)
  File "/home/python/.virtualenvs/django_py3_1.11_02/lib/python3.5/site-packages/rest_framework/views.py", line 480, in dispatch
    response = handler(request, *args, **kwargs)
TypeError: get() got an unexpected keyword argument 'username'
ERROR 2018-09-04 22:32:59,956 basehttp 124 "GET /users/usernames/xiaoming/count/ HTTP/1.1" 500 18558
INFO 2018-09-04 22:34:21,773 basehttp 124 "GET /users/usernames/xiaoming/count/ HTTP/1.1" 200 23
INFO 2018-09-04 22:35:48,600 basehttp 124 "GET /users/usernames/xiaoming/count/ HTTP/1.1" 200 33
WARNING 2018-09-04 22:55:19,355 base 152 Not Found: /users/phones/13513793371/count/
WARNING 2018-09-04 22:55:19,359 basehttp 124 "GET /users/phones/13513793371/count/ HTTP/1.1" 404 2243
INFO 2018-09-04 22:56:34,719 basehttp 124 "GET /users/phones/13513793371/count/ HTTP/1.1" 200 34
WARNING 2018-09-04 22:56:41,685 base 152 Not Found: /users/phones/1351393371/count/
WARNING 2018-09-04 22:56:41,687 basehttp 124 "GET /users/phones/1351393371/count/ HTTP/1.1" 404 2462
WARNING 2018-09-05 18:58:07,444 base 152 Not Found: /verifications/imagecodes/c0c0385a-1d8e-48f1-a00a-9431364acb16/
WARNING 2018-09-05 18:58:07,468 basehttp 124 "GET /verifications/imagecodes/c0c0385a-1d8e-48f1-a00a-9431364acb16/ HTTP/1.1" 404 2421
WARNING 2018-09-05 18:58:17,234 base 152 Not Found: /verifications/imagecodes/254cf5b2-cfc0-46e3-b541-6269a2d0d3f7/
WARNING 2018-09-05 18:58:17,237 basehttp 124 "GET /verifications/imagecodes/254cf5b2-cfc0-46e3-b541-6269a2d0d3f7/ HTTP/1.1" 404 2421
INFO 2018-09-05 19:03:14,290 basehttp 124 "GET /verifications/imagecodes/01f267d4-f27b-4892-8bd9-57ac80229cd3/ HTTP/1.1" 200 3002
INFO 2018-09-05 19:03:18,610 basehttp 124 "GET /verifications/imagecodes/d9669ae2-a42f-46e4-b686-1b8c526e6d2e/ HTTP/1.1" 200 2802
