WARNING 2018-08-24 17:11:15,717 base 152 Not Found: /verifications/imagecodes/bef9bdef-48f8-4a43-b55f-ed14f610f4ab/
WARNING 2018-08-24 17:11:15,721 basehttp 124 "GET /verifications/imagecodes/bef9bdef-48f8-4a43-b55f-ed14f610f4ab/ HTTP/1.1" 404 2113
INFO 2018-08-24 17:12:09,052 basehttp 124 "GET / HTTP/1.1" 200 1714
INFO 2018-08-24 17:12:14,108 basehttp 124 "GET /admin HTTP/1.1" 301 0
INFO 2018-08-24 17:12:14,186 basehttp 124 "GET /admin/ HTTP/1.1" 302 0
INFO 2018-08-24 17:12:14,348 basehttp 124 "GET /admin/login/?next=/admin/ HTTP/1.1" 200 1652
INFO 2018-08-24 17:12:14,391 basehttp 124 "GET /static/admin/css/base.css HTTP/1.1" 200 16066
INFO 2018-08-24 17:12:14,399 basehttp 124 "GET /static/admin/css/login.css HTTP/1.1" 200 1203
INFO 2018-08-24 17:12:14,500 basehttp 124 "GET /static/admin/css/fonts.css HTTP/1.1" 200 423
INFO 2018-08-24 17:12:14,586 basehttp 124 "GET /static/admin/fonts/Roboto-Regular-webfont.woff HTTP/1.1" 200 80304
INFO 2018-08-24 17:12:14,588 basehttp 124 "GET /static/admin/fonts/Roboto-Light-webfont.woff HTTP/1.1" 200 81348
ERROR 2018-09-04 22:32:19,627 exception 135 Internal Server Error: /users/usernames/xiaoming/count/
Traceback (most recent call last):
  File "/home/python/.virtualenvs/django_py3_1.11_02/lib/python3.5/site-packages/django/core/handlers/exception.py", line 41, in inner
    response = get_response(request)
  File "/home/python/.virtualenvs/django_py3_1.11_02/lib/python3.5/site-packages/django/core/handlers/base.py", line 187, in _get_response
    response = self.process_exception_by_middleware(e, request)
  File "/home/python/.virtualenvs/django_py3_1.11_02/lib/python3.5/site-packages/django/core/handlers/base.py", line 185, in _get_response
    response = wrapped_callback(request, *callback_args, **callback_kwargs)
  File "/home/python/.virtualenvs/django_py3_1.11_02/lib/python3.5/site-packages/django/views/decorators/csrf.py", line 58, in wrapped_view
    return view_func(*args, **kwargs)
  File "/home/python/.virtualenvs/django_py3_1.11_02/lib/python3.5/site-packages/django/views/generic/base.py", line 68, in view
    return self.dispatch(request, *args, **kwargs)
  File "/home/python/.virtualenvs/django_py3_1.11_02/lib/python3.5/site-packages/rest_framework/views.py", line 483, in dispatch
    response = self.handle_exception(exc)
  File "/home/python/.virtualenvs/django_py3_1.11_02/lib/python3.5/site-packages/rest_framework/views.py", line 443, in handle_exception
    self.raise_uncaught_exception(exc)
  File "/home/python/.virtualenvs/django_py3_1.11_02/lib/python3.5/site-packages/rest_framework/views.py", line 480, in dispatch
    response = handler(request, *args, **kwargs)
TypeError: get() got an unexpected keyword argument 'username'
ERROR 2018-09-04 22:32:19,753 basehttp 124 "GET /users/usernames/xiaoming/count/ HTTP/1.1" 500 18558
ERROR 2018-09-04 22:32:59,827 exception 135 Internal Server Error: /users/usernames/xiaoming/count/
Traceback (most recent call last):
  File "/home/python/.virtualenvs/django_py3_1.11_02/lib/python3.5/site-packages/django/core/handlers/exception.py", line 41, in inner
    response = get_response(request)
  File "/home/python/.virtualenvs/django_py3_1.11_02/lib/python3.5/site-packages/django/core/handlers/base.py", line 187, in _get_response
    response = self.process_exception_by_middleware(e, request)
  File "/home/python/.virtualenvs/django_py3_1.11_02/lib/python3.5/site-packages/django/core/handlers/base.py", line 185, in _get_response
    response = wrapped_callback(request, *callback_args, **callback_kwargs)
  File "/home/python/.virtualenvs/django_py3_1.11_02/lib/python3.5/site-packages/django/views/decorators/csrf.py", line 58, in wrapped_view
    return view_func(*args, **kwargs)
  File "/home/python/.virtualenvs/django_py3_1.11_02/lib/python3.5/site-packages/django/views/generic/base.py", line 68, in view
    return self.dispatch(request, *args, **kwargs)
  File "/home/python/.virtualenvs/django_py3_1.11_02/lib/python3.5/site-packages/rest_framework/views.py", line 483, in dispatch
    response = self.handle_exception(exc)
  File "/home/python/.virtualenvs/django_py3_1.11_02/lib/python3.5/site-packages/rest_framework/views.py", line 443, in handle_exception
    self.raise_uncaught_exception(exc)
  File "/home/python/.virtualenvs/django_py3_1.11_02/lib/python3.5/site-packages/rest_framework/views.py", line 480, in dispatch
    response = handler(request, *args, **kwargs)
TypeError: get() got an unexpected keyword argument 'username'
ERROR 2018-09-04 22:32:59,956 basehttp 124 "GET /users/usernames/xiaoming/count/ HTTP/1.1" 500 18558
INFO 2018-09-04 22:34:21,773 basehttp 124 "GET /users/usernames/xiaoming/count/ HTTP/1.1" 200 23
INFO 2018-09-04 22:35:48,600 basehttp 124 "GET /users/usernames/xiaoming/count/ HTTP/1.1" 200 33
WARNING 2018-09-04 22:55:19,355 base 152 Not Found: /users/phones/13513793371/count/
WARNING 2018-09-04 22:55:19,359 basehttp 124 "GET /users/phones/13513793371/count/ HTTP/1.1" 404 2243
INFO 2018-09-04 22:56:34,719 basehttp 124 "GET /users/phones/13513793371/count/ HTTP/1.1" 200 34
WARNING 2018-09-04 22:56:41,685 base 152 Not Found: /users/phones/1351393371/count/
WARNING 2018-09-04 22:56:41,687 basehttp 124 "GET /users/phones/1351393371/count/ HTTP/1.1" 404 2462
WARNING 2018-09-05 18:58:07,444 base 152 Not Found: /verifications/imagecodes/c0c0385a-1d8e-48f1-a00a-9431364acb16/
WARNING 2018-09-05 18:58:07,468 basehttp 124 "GET /verifications/imagecodes/c0c0385a-1d8e-48f1-a00a-9431364acb16/ HTTP/1.1" 404 2421
WARNING 2018-09-05 18:58:17,234 base 152 Not Found: /verifications/imagecodes/254cf5b2-cfc0-46e3-b541-6269a2d0d3f7/
WARNING 2018-09-05 18:58:17,237 basehttp 124 "GET /verifications/imagecodes/254cf5b2-cfc0-46e3-b541-6269a2d0d3f7/ HTTP/1.1" 404 2421
INFO 2018-09-05 19:03:14,290 basehttp 124 "GET /verifications/imagecodes/01f267d4-f27b-4892-8bd9-57ac80229cd3/ HTTP/1.1" 200 3002
INFO 2018-09-05 19:03:18,610 basehttp 124 "GET /verifications/imagecodes/d9669ae2-a42f-46e4-b686-1b8c526e6d2e/ HTTP/1.1" 200 2802
INFO 2018-09-05 19:36:09,466 basehttp 124 "GET /verifications/imagecodes/1ecb609c-93a6-4483-b944-b3cee2b0b99a/ HTTP/1.1" 200 2764
INFO 2018-09-05 19:36:14,511 basehttp 124 "GET /users/usernames/xiaoming/count/ HTTP/1.1" 200 33
INFO 2018-09-05 19:36:25,998 basehttp 124 "GET /users/phones/15013689309/count/ HTTP/1.1" 200 34
ERROR 2018-09-05 19:36:33,808 exception 135 Internal Server Error: /verifications/smscodes/15013689309/
Traceback (most recent call last):
  File "/home/python/.virtualenvs/django_py3_1.11/lib/python3.5/site-packages/django/core/handlers/exception.py", line 41, in inner
    response = get_response(request)
  File "/home/python/.virtualenvs/django_py3_1.11/lib/python3.5/site-packages/django/core/handlers/base.py", line 187, in _get_response
    response = self.process_exception_by_middleware(e, request)
  File "/home/python/.virtualenvs/django_py3_1.11/lib/python3.5/site-packages/django/core/handlers/base.py", line 185, in _get_response
    response = wrapped_callback(request, *callback_args, **callback_kwargs)
  File "/home/python/.virtualenvs/django_py3_1.11/lib/python3.5/site-packages/django/views/decorators/csrf.py", line 58, in wrapped_view
    return view_func(*args, **kwargs)
  File "/home/python/.virtualenvs/django_py3_1.11/lib/python3.5/site-packages/django/views/generic/base.py", line 68, in view
    return self.dispatch(request, *args, **kwargs)
  File "/home/python/.virtualenvs/django_py3_1.11/lib/python3.5/site-packages/rest_framework/views.py", line 483, in dispatch
    response = self.handle_exception(exc)
  File "/home/python/.virtualenvs/django_py3_1.11/lib/python3.5/site-packages/rest_framework/views.py", line 443, in handle_exception
    self.raise_uncaught_exception(exc)
  File "/home/python/.virtualenvs/django_py3_1.11/lib/python3.5/site-packages/rest_framework/views.py", line 480, in dispatch
    response = handler(request, *args, **kwargs)
TypeError: get() got an unexpected keyword argument 'mobile'
INFO 2018-09-05 19:36:33,842 basehttp 124 "GET /users/phones/15013689309/count/ HTTP/1.1" 200 34
ERROR 2018-09-05 19:36:33,924 basehttp 124 "GET /verifications/smscodes/15013689309/?text=3hpe&image_code_id=1ecb609c-93a6-4483-b944-b3cee2b0b99a HTTP/1.1" 500 18256
INFO 2018-09-05 19:38:32,527 basehttp 124 "GET /verifications/imagecodes/9cffa624-02da-4a26-9e9c-ad84a568d7c2/ HTTP/1.1" 200 3305
INFO 2018-09-05 19:38:35,980 basehttp 124 "GET /users/phones/15013689309/count/ HTTP/1.1" 200 34
ERROR 2018-09-05 19:38:41,267 exception 135 Internal Server Error: /verifications/smscodes/15013689309/
Traceback (most recent call last):
  File "/home/python/.virtualenvs/django_py3_1.11/lib/python3.5/site-packages/django/core/handlers/exception.py", line 41, in inner
    response = get_response(request)
  File "/home/python/.virtualenvs/django_py3_1.11/lib/python3.5/site-packages/django/core/handlers/base.py", line 187, in _get_response
    response = self.process_exception_by_middleware(e, request)
  File "/home/python/.virtualenvs/django_py3_1.11/lib/python3.5/site-packages/django/core/handlers/base.py", line 185, in _get_response
    response = wrapped_callback(request, *callback_args, **callback_kwargs)
  File "/home/python/.virtualenvs/django_py3_1.11/lib/python3.5/site-packages/django/views/decorators/csrf.py", line 58, in wrapped_view
    return view_func(*args, **kwargs)
  File "/home/python/.virtualenvs/django_py3_1.11/lib/python3.5/site-packages/django/views/generic/base.py", line 68, in view
    return self.dispatch(request, *args, **kwargs)
  File "/home/python/.virtualenvs/django_py3_1.11/lib/python3.5/site-packages/rest_framework/views.py", line 483, in dispatch
    response = self.handle_exception(exc)
  File "/home/python/.virtualenvs/django_py3_1.11/lib/python3.5/site-packages/rest_framework/views.py", line 443, in handle_exception
    self.raise_uncaught_exception(exc)
  File "/home/python/.virtualenvs/django_py3_1.11/lib/python3.5/site-packages/rest_framework/views.py", line 480, in dispatch
    response = handler(request, *args, **kwargs)
TypeError: get() got an unexpected keyword argument 'mobile'
INFO 2018-09-05 19:38:41,300 basehttp 124 "GET /users/phones/15013689309/count/ HTTP/1.1" 200 34
ERROR 2018-09-05 19:38:41,442 basehttp 124 "GET /verifications/smscodes/15013689309/?text=lihg&image_code_id=9cffa624-02da-4a26-9e9c-ad84a568d7c2 HTTP/1.1" 500 18256
INFO 2018-09-05 19:40:06,814 basehttp 124 "GET /verifications/imagecodes/392de345-4164-4aed-9464-0456a00b42d0/ HTTP/1.1" 200 3168
INFO 2018-09-05 19:40:09,787 basehttp 124 "GET /users/phones/15013689309/count/ HTTP/1.1" 200 34
INFO 2018-09-05 19:40:11,529 basehttp 124 "GET /verifications/imagecodes/e85b2a17-58b1-4cb9-a1dd-bc353434fafd/ HTTP/1.1" 200 3225
INFO 2018-09-05 19:40:12,299 basehttp 124 "GET /verifications/imagecodes/83ddab88-f817-44e2-b469-32c0d01dd3c4/ HTTP/1.1" 200 2766
INFO 2018-09-05 19:40:13,044 basehttp 124 "GET /verifications/imagecodes/10ec6fdb-cbe8-4e9c-a8b9-a792ca775a83/ HTTP/1.1" 200 3158
INFO 2018-09-05 19:40:14,281 basehttp 124 "GET /verifications/imagecodes/23a7f9ab-a27d-4336-b1f0-f239e3cb88ef/ HTTP/1.1" 200 3585
INFO 2018-09-05 19:40:20,241 basehttp 124 "GET /users/phones/15013689309/count/ HTTP/1.1" 200 34
INFO 2018-09-05 19:40:57,396 basehttp 124 "GET /verifications/smscodes/15013689309/?text=wabq&image_code_id=23a7f9ab-a27d-4336-b1f0-f239e3cb88ef HTTP/1.1" 200 16
INFO 2018-09-05 20:37:59,663 basehttp 124 "GET /verifications/imagecodes/e10c5f74-da15-4503-809f-b08a10d9073c/ HTTP/1.1" 200 3161
INFO 2018-09-05 20:38:03,829 basehttp 124 "GET /users/usernames/xiaoming/count/ HTTP/1.1" 200 33
INFO 2018-09-05 20:38:12,055 basehttp 124 "GET /users/phones/15013689309/count/ HTTP/1.1" 200 34
INFO 2018-09-05 20:38:18,505 basehttp 124 "GET /verifications/smscodes/15013689309/?text=divl&image_code_id=e10c5f74-da15-4503-809f-b08a10d9073c HTTP/1.1" 200 16
INFO 2018-09-05 20:38:18,508 basehttp 124 "GET /users/phones/15013689309/count/ HTTP/1.1" 200 34
INFO 2018-09-05 20:38:26,698 basehttp 124 "OPTIONS /users/ HTTP/1.1" 200 0
ERROR 2018-09-05 20:38:26,703 exception 135 Internal Server Error: /users/
Traceback (most recent call last):
  File "/home/python/.virtualenvs/django_py3_1.11/lib/python3.5/site-packages/django/core/handlers/exception.py", line 41, in inner
    response = get_response(request)
  File "/home/python/.virtualenvs/django_py3_1.11/lib/python3.5/site-packages/django/core/handlers/base.py", line 187, in _get_response
    response = self.process_exception_by_middleware(e, request)
  File "/home/python/.virtualenvs/django_py3_1.11/lib/python3.5/site-packages/django/core/handlers/base.py", line 185, in _get_response
    response = wrapped_callback(request, *callback_args, **callback_kwargs)
  File "/home/python/.virtualenvs/django_py3_1.11/lib/python3.5/site-packages/django/views/decorators/csrf.py", line 58, in wrapped_view
    return view_func(*args, **kwargs)
  File "/home/python/.virtualenvs/django_py3_1.11/lib/python3.5/site-packages/django/views/generic/base.py", line 68, in view
    return self.dispatch(request, *args, **kwargs)
  File "/home/python/.virtualenvs/django_py3_1.11/lib/python3.5/site-packages/rest_framework/views.py", line 466, in dispatch
    request = self.initialize_request(request, *args, **kwargs)
  File "/home/python/.virtualenvs/django_py3_1.11/lib/python3.5/site-packages/rest_framework/views.py", line 367, in initialize_request
    parsers=self.get_parsers(),
  File "/home/python/.virtualenvs/django_py3_1.11/lib/python3.5/site-packages/rest_framework/views.py", line 256, in get_parsers
    return [parser() for parser in self.parser_classes]
TypeError: 'SerializerMetaclass' object is not iterable
INFO 2018-09-05 20:38:26,708 basehttp 124 "GET /users/usernames/xiaoming/count/ HTTP/1.1" 200 33
INFO 2018-09-05 20:38:26,717 basehttp 124 "GET /users/phones/15013689309/count/ HTTP/1.1" 200 34
ERROR 2018-09-05 20:38:26,951 basehttp 124 "POST /users/ HTTP/1.1" 500 91149
INFO 2018-09-05 20:46:07,205 basehttp 124 "GET /verifications/imagecodes/ca2f944a-bf3c-4d55-a7d5-acd8bd321393/ HTTP/1.1" 200 3098
INFO 2018-09-05 20:46:11,322 basehttp 124 "GET /users/usernames/xiaoming/count/ HTTP/1.1" 200 33
INFO 2018-09-05 20:46:22,159 basehttp 124 "GET /users/phones/15013689309/count/ HTTP/1.1" 200 34
INFO 2018-09-05 20:46:22,239 basehttp 124 "GET /verifications/imagecodes/c900ce89-3721-4d00-a3f1-19a04f1dc459/ HTTP/1.1" 200 3346
INFO 2018-09-05 20:46:22,447 basehttp 124 "GET /verifications/imagecodes/0effd1c0-645e-4837-a9cc-85abadf4f6da/ HTTP/1.1" 200 3019
INFO 2018-09-05 20:46:24,176 basehttp 124 "GET /verifications/imagecodes/391a488e-70f2-41ea-b83e-702d12311773/ HTTP/1.1" 200 3095
INFO 2018-09-05 20:46:25,336 basehttp 124 "GET /verifications/imagecodes/3256f1b8-8718-4de6-9248-35f3cd7f9e07/ HTTP/1.1" 200 3023
INFO 2018-09-05 20:46:38,521 basehttp 124 "GET /users/phones/15013689309/count/ HTTP/1.1" 200 34
INFO 2018-09-05 20:46:38,522 basehttp 124 "GET /verifications/smscodes/15013689309/?text=gymb&image_code_id=3256f1b8-8718-4de6-9248-35f3cd7f9e07 HTTP/1.1" 200 16
INFO 2018-09-05 20:46:47,638 basehttp 124 "GET /users/usernames/xiaoming/count/ HTTP/1.1" 200 33
ERROR 2018-09-05 20:46:47,647 exception 135 Internal Server Error: /users/
Traceback (most recent call last):
  File "/home/python/.virtualenvs/django_py3_1.11/lib/python3.5/site-packages/django/core/handlers/exception.py", line 41, in inner
    response = get_response(request)
  File "/home/python/.virtualenvs/django_py3_1.11/lib/python3.5/site-packages/django/core/handlers/base.py", line 187, in _get_response
    response = self.process_exception_by_middleware(e, request)
  File "/home/python/.virtualenvs/django_py3_1.11/lib/python3.5/site-packages/django/core/handlers/base.py", line 185, in _get_response
    response = wrapped_callback(request, *callback_args, **callback_kwargs)
  File "/home/python/.virtualenvs/django_py3_1.11/lib/python3.5/site-packages/django/views/decorators/csrf.py", line 58, in wrapped_view
    return view_func(*args, **kwargs)
  File "/home/python/.virtualenvs/django_py3_1.11/lib/python3.5/site-packages/django/views/generic/base.py", line 68, in view
    return self.dispatch(request, *args, **kwargs)
  File "/home/python/.virtualenvs/django_py3_1.11/lib/python3.5/site-packages/rest_framework/views.py", line 466, in dispatch
    request = self.initialize_request(request, *args, **kwargs)
  File "/home/python/.virtualenvs/django_py3_1.11/lib/python3.5/site-packages/rest_framework/views.py", line 367, in initialize_request
    parsers=self.get_parsers(),
  File "/home/python/.virtualenvs/django_py3_1.11/lib/python3.5/site-packages/rest_framework/views.py", line 256, in get_parsers
    return [parser() for parser in self.parser_classes]
TypeError: 'SerializerMetaclass' object is not iterable
INFO 2018-09-05 20:46:47,653 basehttp 124 "GET /users/phones/15013689309/count/ HTTP/1.1" 200 34
ERROR 2018-09-05 20:46:47,965 basehttp 124 "POST /users/ HTTP/1.1" 500 91149
INFO 2018-09-05 20:52:43,505 basehttp 124 "GET /verifications/imagecodes/3800f8ba-0925-4dfa-a767-f74eb007d705/ HTTP/1.1" 200 3256
INFO 2018-09-05 20:52:45,054 basehttp 124 "GET /users/usernames/xiaoming/count/ HTTP/1.1" 200 33
INFO 2018-09-05 20:52:53,180 basehttp 124 "GET /users/phones/15013689309/count/ HTTP/1.1" 200 34
INFO 2018-09-05 20:52:53,711 basehttp 124 "GET /verifications/imagecodes/01267434-cb55-43c3-8a43-4ad8884ef52d/ HTTP/1.1" 200 3254
INFO 2018-09-05 20:52:55,851 basehttp 124 "GET /verifications/imagecodes/a3938710-e8de-4497-9d20-5726f74ab3b2/ HTTP/1.1" 200 3147
INFO 2018-09-05 20:53:01,465 basehttp 124 "GET /verifications/smscodes/15013689309/?text=dayr&image_code_id=a3938710-e8de-4497-9d20-5726f74ab3b2 HTTP/1.1" 200 16
INFO 2018-09-05 20:53:01,483 basehttp 124 "GET /users/phones/15013689309/count/ HTTP/1.1" 200 34
INFO 2018-09-05 20:53:09,030 basehttp 124 "OPTIONS /users/ HTTP/1.1" 200 0
INFO 2018-09-05 20:53:09,044 basehttp 124 "GET /users/phones/15013689309/count/ HTTP/1.1" 200 34
INFO 2018-09-05 20:53:09,074 basehttp 124 "GET /users/usernames/xiaoming/count/ HTTP/1.1" 200 33
INFO 2018-09-05 20:53:46,505 basehttp 124 "POST /users/ HTTP/1.1" 201 53
INFO 2018-09-06 10:40:34,539 basehttp 124 "OPTIONS /users/auths/ HTTP/1.1" 200 0
INFO 2018-09-06 10:40:58,870 basehttp 124 "POST /users/auths/ HTTP/1.1" 200 211
INFO 2018-09-06 10:41:05,683 basehttp 124 "OPTIONS /users/infos/ HTTP/1.1" 200 0
WARNING 2018-09-06 10:41:05,770 base 152 Not Found: /users/infos/
WARNING 2018-09-06 10:41:05,773 basehttp 124 "GET /users/infos/ HTTP/1.1" 404 2860
